<?xml version="1.0"?>
<robot name="ackermann_base" xmlns:xacro="http://ros.org/wiki/xacro">
  <xacro:include filename="$(find arti_base_control_examples)/urdf/wheel.urdf.xacro"/>

  <!-- Main Links -->

  <link name="base_link"/>

  <link name="base_footprint"/>

  <joint name="base_link_to_base_footprint" type="fixed">
    <parent link="base_link"/>
    <child link="base_footprint"/>
    <origin xyz="0 0 -0.15"/>
  </joint>

  <!-- Body -->

  <link name="body">
    <visual>
      <geometry>
        <cylinder length="0.05" radius="0.3"/>
      </geometry>
      <material name="dark_gray">
        <color rgba="0.2 0.2 0.2 1.0"/>
      </material>
    </visual>
  </link>

  <joint name="body_joint" type="fixed">
    <parent link="base_link"/>
    <child link="body"/>
    <origin xyz="0.0 0.0 0.0"/>
  </joint>

  <!-- Wheels -->

  <xacro:wheel name="left_wheel"/>
  <xacro:wheel name="right_wheel"/>

  <joint name="left_wheel_joint" type="continuous">
    <parent link="base_link"/>
    <child link="left_wheel"/>
    <origin rpy="-1.57075 0 0" xyz="0.0 0.35 0.0"/>
    <axis xyz="0 0 1"/>
  </joint>

  <joint name="right_wheel_joint" type="continuous">
    <parent link="base_link"/>
    <child link="right_wheel"/>
    <origin rpy="1.57075 0 0" xyz="0.0 -0.35 0.0"/>
    <axis xyz="0 0 -1"/>
  </joint>
</robot>

